Workbook
Name Scales_Input_Table: 'Scales Input Table'!$A$1:$T$1

Sheet Summary Sheet
A3: Number of Cylinders | B3: Min of Car Only | C3: Average of Car Only | D3: Max of Car Only
A4: 1 | B4: 323 | C4: 389.3913 | D4: 475
A5: 2 | B5: 345 | C5: 444.625 | D5: 511
A6: 3 | B6: 435 | C6: 492 | D6: 549
A7: 4 | B7: 383 | C7: 474.23529 | D7: 712
A8: (blank)
A9: Grand Total | B9: 323 | C9: 452.92079 | D9: 712

Sheet Scales Input Table
A1: Car Number | B1: School Name | C1: Front Left | D1: Front Right | E1: Rear Left | F1: Rear Right | G1: Car w/Driver | H1: VOID | I1: Car Only | J1: Fuel Level | K1: VOID2 | L1: Driver Weight | M1: Engine Cylinders | N1: Engine Disp (cc) | O1: Turbo | P1: Frame | Q1: Aerodynamic Package | R1: Wheel Diameter | S1: Wheelbase | T1: Car Weight in Kg | U1: Driver Weight in Kg | V1: Front % | W1: Front # | X1: Left % | Y1: Left #
A2: 1 | B2: Universitat Stuttgart | C2: 120 | D2: 161 | E2: 158 | F2: 119 | G2: 558 | I2: 383 | J2: HALF | L2: =IF($G2="","",$G2-$I2) -> 175 | M2: 4 | N2: 599 | O2: No | P2: Hybrid | Q2: Full Package | R2: 10" | S2: =1630/25.4 -> 64.173228 | T2: =$I2*0.453592 -> 173.72574 | U2: =$L2*0.453592 -> 79.3786 | V2: =IF($G2="","",($C2+$D2)/$G2) -> 0.50358423 | W2: =($C2+$D2) -> 281 | X2: =IF($G2="","",($C2+$E2)/$G2) -> 0.49820789 | Y2: =($C2+$E2) -> 278
A3: 2 | B3: Graz Technical Univ | C3: 102 | D3: 130 | E3: 152 | F3: 128 | G3: 511 | I3: 342 | J3: HALF | L3: =IF($G3="","",$G3-$I3) -> 169 | M3: 1 | N3: 510 | O3: No | P3: Monocoque | Q3: Full Package | R3: 10" | S3: =1550/25.4 -> 61.023622 | T3: =$I3*0.453592 -> 155.12846 | U3: =$L3*0.453592 -> 76.657048 | V3: =IF($G3="","",($C3+$D3)/$G3) -> 0.45401174 | W3: =($C3+$D3) -> 232 | X3: =IF($G3="","",($C3+$E3)/$G3) -> 0.49706458 | Y3: =($C3+$E3) -> 254
A4: 5 | B4: Ecole De Technologie Superieure | C4: 113 | D4: 107 | E4: 123 | F4: 130 | G4: 472 | I4: 325 | J4: HALF | L4: =IF($G4="","",$G4-$I4) -> 147 | M4: 1 | N4: 449 | O4: Yes, No Cooler | P4: Monocoque | Q4: Wings Only | R4: 10" | S4: 60.25 | T4: =$I4*0.453592 -> 147.4174 | U4: =$L4*0.453592 -> 66.678024 | V4: =IF($G4="","",($C4+$D4)/$G4) -> 0.46610169 | W4: =($C4+$D4) -> 220 | X4: =IF($G4="","",($C4+$E4)/$G4) -> 0.5 | Y4: =($C4+$E4) -> 236
A5: 6 | B5: Univ of Akron | C5: 142 | D5: 152 | E5: 132 | F5: 129 | G5: 555 | I5: 373 | J5: HALF | L5: =IF($G5="","",$G5-$I5) -> 182 | M5: 1 | N5: 450 | O5: No | P5: Hybrid | Q5: Full Package | R5: 13" | S5: 60.2 | T5: =$I5*0.453592 -> 169.18982 | U5: =$L5*0.453592 -> 82.553744 | V5: =IF($G5="","",($C5+$D5)/$G5) -> 0.52972973 | W5: =($C5+$D5) -> 294 | X5: =IF($G5="","",($C5+$E5)/$G5) -> 0.49369369 | Y5: =($C5+$E5) -> 274
A6: 7 | B6: Carleton Univ | C6: 119 | D6: 135 | E6: 137 | F6: 125 | G6: 518 | I6: 358 | J6: EMPTY | L6: =IF($G6="","",$G6-$I6) -> 160 | M6: 1 | N6: 450 | O6: No | P6: Tube Frame | Q6: Full Package | R6: 10" | S6: 61 | T6: =$I6*0.453592 -> 162.38594 | U6: =$L6*0.453592 -> 72.57472 | V6: =IF($G6="","",($C6+$D6)/$G6) -> 0.49034749 | W6: =($C6+$D6) -> 254 | X6: =IF($G6="","",($C6+$E6)/$G6) -> 0.49420849 | Y6: =($C6+$E6) -> 256
A7: 8 | B7: Univ of Wisconsin - Madison | C7: 127 | D7: 126 | E7: 148 | F7: 144 | G7: 545 | I7: 363 | J7: EMPTY | L7: =IF($G7="","",$G7-$I7) -> 182 | M7: 1 | N7: 449 | O7: Yes, No Cooler | P7: Hybrid | Q7: Wings Only | R7: 10" | S7: 63 | T7: =$I7*0.453592 -> 164.6539 | U7: =$L7*0.453592 -> 82.553744 | V7: =IF($G7="","",($C7+$D7)/$G7) -> 0.46422018 | W7: =($C7+$D7) -> 253 | X7: =IF($G7="","",($C7+$E7)/$G7) -> 0.50458716 | Y7: =($C7+$E7) -> 275
A8: 9 | B8: Univ of Michigan - Ann Arbor | C8: 134 | D8: 154 | E8: 171 | F8: 157 | G8: 616 | I8: 433 | J8: EMPTY | L8: =IF($G8="","",$G8-$I8) -> 183 | M8: 4 | N8: 599 | O8: Yes, No Cooler | P8: Hybrid | Q8: Full Package | R8: 10" | S8: 61 | T8: =$I8*0.453592 -> 196.40534 | U8: =$L8*0.453592 -> 83.007336 | V8: =IF($G8="","",($C8+$D8)/$G8) -> 0.46753247 | W8: =($C8+$D8) -> 288 | X8: =IF($G8="","",($C8+$E8)/$G8) -> 0.49512987 | Y8: =($C8+$E8) -> 305
A9: 10 | B9: AGH Univ of Science and Technology | C9: 121 | D9: 139 | E9: 172 | F9: 154 | G9: 586 | I9: 427 | J9: FULL | L9: =IF($G9="","",$G9-$I9) -> 159 | M9: 4 | N9: 599 | O9: No | P9: Tube Frame | Q9: Wings Only | R9: 10" | S9: =1560/25.4 -> 61.417323 | T9: =$I9*0.453592 -> 193.68378 | U9: =$L9*0.453592 -> 72.121128 | V9: =IF($G9="","",($C9+$D9)/$G9) -> 0.44368601 | W9: =($C9+$D9) -> 260 | X9: =IF($G9="","",($C9+$E9)/$G9) -> 0.5 | Y9: =($C9+$E9) -> 293
A10: 11 | B10: Michigan State Univ | C10: 139 | D10: 161 | E10: 162 | F10: 137 | G10: 599 | I10: 427 | J10: HALF | L10: =IF($G10="","",$G10-$I10) -> 172 | M10: 4 | N10: 599 | O10: No | P10: Hybrid | Q10: Full Package | R10: 10" | S10: 60.5 | T10: =$I10*0.453592 -> 193.68378 | U10: =$L10*0.453592 -> 78.017824 | V10: =IF($G10="","",($C10+$D10)/$G10) -> 0.50083472 | W10: =($C10+$D10) -> 300 | X10: =IF($G10="","",($C10+$E10)/$G10) -> 0.50250417 | Y10: =($C10+$E10) -> 301
A11: 12 | B11: Purdue Univ - W Lafayette | C11: 139 | D11: 167 | E11: 169 | F11: 138 | G11: 612 | I11: 455 | J11: HALF | L11: =IF($G11="","",$G11-$I11) -> 157 | M11: 4 | N11: 599 | O11: No | P11: Tube Frame | Q11: Full Package | R11: 10" | S11: 61 | T11: =$I11*0.453592 -> 206.38436 | U11: =$L11*0.453592 -> 71.213944 | V11: =IF($G11="","",($C11+$D11)/$G11) -> 0.5 | W11: =($C11+$D11) -> 306 | X11: =IF($G11="","",($C11+$E11)/$G11) -> 0.50326797 | Y11: =($C11+$E11) -> 308
A12: 14 | B12: Ecole Polytechnique Montreal | C12: 145 | D12: 165 | E12: 161 | F12: 141 | G12: 613 | I12: 410 | J12: EMPTY | L12: =IF($G12="","",$G12-$I12) -> 203 | M12: 1 | N12: 449 | O12: No | P12: Tube Frame | Q12: Wings Only | R12: 10" | S12: =1579/25.4 -> 62.165354 | T12: =$I12*0.453592 -> 185.97272 | U12: =$L12*0.453592 -> 92.079176 | V12: =IF($G12="","",($C12+$D12)/$G12) -> 0.50570962 | W12: =($C12+$D12) -> 310 | X12: =IF($G12="","",($C12+$E12)/$G12) -> 0.49918434 | Y12: =($C12+$E12) -> 306
A13: 16 | B13: Kookmin Univ | C13: 119 | D13: 165 | E13: 174 | F13: 131 | G13: 590 | I13: 463 | J13: EMPTY | L13: =IF($G13="","",$G13-$I13) -> 127 | M13: 4 | N13: 600 | O13: No | P13: Hybrid | Q13: Full Package | R13: 10" | S13: =1530/25.4 -> 60.23622 | T13: =$I13*0.453592 -> 210.0131 | U13: =$L13*0.453592 -> 57.606184 | V13: =IF($G13="","",($C13+$D13)/$G13) -> 0.48135593 | W13: =($C13+$D13) -> 284 | X13: =IF($G13="","",($C13+$E13)/$G13) -> 0.49661017 | Y13: =($C13+$E13) -> 293
A14: 17 | B14: Bradley Univ | C14: 176 | D14: 165 | E14: 169 | F14: 165 | G14: 674 | I14: 511 | J14: EMPTY | L14: =IF($G14="","",$G14-$I14) -> 163 | M14: 2 | N14: 479 | O14: No | P14: Tube Frame | Q14: None | R14: 13" | S14: 63 | T14: =$I14*0.453592 -> 231.78551 | U14: =$L14*0.453592 -> 73.935496 | V14: =IF($G14="","",($C14+$D14)/$G14) -> 0.50593472 | W14: =($C14+$D14) -> 341 | X14: =IF($G14="","",($C14+$E14)/$G14) -> 0.51186944 | Y14: =($C14+$E14) -> 345
A15: 18 | B15: Univ of Alabama - Tuscaloosa | C15: 129 | D15: 168 | E15: 177 | F15: 139 | G15: 614 | I15: 445 | J15: FULL | L15: =IF($G15="","",$G15-$I15) -> 169 | M15: 4 | N15: 600 | O15: No | P15: Tube Frame | Q15: Wings Only | R15: 10" | S15: 62 | T15: =$I15*0.453592 -> 201.84844 | U15: =$L15*0.453592 -> 76.657048 | V15: =IF($G15="","",($C15+$D15)/$G15) -> 0.48371336 | W15: =($C15+$D15) -> 297 | X15: =IF($G15="","",($C15+$E15)/$G15) -> 0.49837134 | Y15: =($C15+$E15) -> 306
A16: 19 | B16: North Carolina State Univ - Raleigh | C16: 143 | D16: 165 | E16: 165 | F16: 153 | G16: 625 | I16: 466 | J16: EMPTY | L16: =IF($G16="","",$G16-$I16) -> 159 | M16: 4 | N16: 600 | O16: No | P16: Tube Frame | Q16: Full Package | R16: 10" | S16: 61 | T16: =$I16*0.453592 -> 211.37387 | U16: =$L16*0.453592 -> 72.121128 | V16: =IF($G16="","",($C16+$D16)/$G16) -> 0.4928 | W16: =($C16+$D16) -> 308 | X16: =IF($G16="","",($C16+$E16)/$G16) -> 0.4928 | Y16: =($C16+$E16) -> 308
A17: 20 | B17: Florida Inst of Tech | C17: 163 | D17: 186 | E17: 193 | F17: 181 | G17: 723 | I17: 536 | J17: HALF | L17: =IF($G17="","",$G17-$I17) -> 187 | M17: 4 | N17: 599 | O17: No | P17: Tube Frame | Q17: Wings Only | R17: 10" | S17: =1651/25.4 -> 65 | T17: =$I17*0.453592 -> 243.12531 | U17: =$L17*0.453592 -> 84.821704 | V17: =IF($G17="","",($C17+$D17)/$G17) -> 0.48271093 | W17: =($C17+$D17) -> 349 | X17: =IF($G17="","",($C17+$E17)/$G17) -> 0.49239281 | Y17: =($C17+$E17) -> 356
A18: 21 | B18: Univ of Florida | C18: 144 | D18: 156 | E18: 175 | F18: 159 | G18: 633 | I18: 474 | J18: HALF | L18: =IF($G18="","",$G18-$I18) -> 159 | M18: 4 | N18: 599 | O18: No | P18: Tube Frame | Q18: Full Package | R18: 13" | S18: 61 | T18: =$I18*0.453592 -> 215.00261 | U18: =$L18*0.453592 -> 72.121128 | V18: =IF($G18="","",($C18+$D18)/$G18) -> 0.47393365 | W18: =($C18+$D18) -> 300 | X18: =IF($G18="","",($C18+$E18)/$G18) -> 0.50394945 | Y18: =($C18+$E18) -> 319
A19: 23 | B19: Rensselaer Polytechnic Inst | C19: 123 | D19: 151 | E19: 159 | F19: 138 | G19: 571 | I19: 433 | J19: HALF | L19: =IF($G19="","",$G19-$I19) -> 138 | M19: 4 | N19: 599 | O19: No | P19: Tube Frame | Q19: Wings Only | R19: 10" | S19: 60.5 | T19: =$I19*0.453592 -> 196.40534 | U19: =$L19*0.453592 -> 62.595696 | V19: =IF($G19="","",($C19+$D19)/$G19) -> 0.47985989 | W19: =($C19+$D19) -> 274 | X19: =IF($G19="","",($C19+$E19)/$G19) -> 0.4938704 | Y19: =($C19+$E19) -> 282
A20: 24 | B20: Univ of Toledo | C20: 124 | D20: 144 | E20: 138 | F20: 132 | G20: 538 | I20: 386 | J20: EMPTY | L20: =IF($G20="","",$G20-$I20) -> 152 | M20: 1 | N20: 450 | O20: No | P20: Tube Frame | Q20: Wings Only | R20: 10" | S20: 60 | T20: =$I20*0.453592 -> 175.08651 | U20: =$L20*0.453592 -> 68.945984 | V20: =IF($G20="","",($C20+$D20)/$G20) -> 0.49814126 | W20: =($C20+$D20) -> 268 | X20: =IF($G20="","",($C20+$E20)/$G20) -> 0.48698885 | Y20: =($C20+$E20) -> 262
A21: 25 | B21: Florida A&M Univ/Florida State Univ | L21: =IF($G21="","",$G21-$I21) | T21: =$I21*0.453592 -> 0 | U21: =$L21*0.453592 -> #VALUE! | V21: =IF($G21="","",($C21+$D21)/$G21) | W21: =($C21+$D21) -> 0 | X21: =IF($G21="","",($C21+$E21)/$G21) | Y21: =($C21+$E21) -> 0
A22: 26 | B22: Purdue Univ - Northwest | C22: 175 | D22: 166 | E22: 136 | F22: 143 | G22: 620 | I22: 456 | J22: HALF | L22: =IF($G22="","",$G22-$I22) -> 164 | M22: 4 | N22: 599 | O22: No | P22: Tube Frame | Q22: None | R22: 10" | S22: =1588/25.4 -> 62.519685 | T22: =$I22*0.453592 -> 206.83795 | U22: =$L22*0.453592 -> 74.389088 | V22: =IF($G22="","",($C22+$D22)/$G22) -> 0.55 | W22: =($C22+$D22) -> 341 | X22: =IF($G22="","",($C22+$E22)/$G22) -> 0.5016129 | Y22: =($C22+$E22) -> 311
A23: 29 | B23: Univ of Cincinnati | C23: 140 | D23: 136 | E23: 143 | F23: 145 | G23: 564 | I23: 421 | J23: HALF | L23: =IF($G23="","",$G23-$I23) -> 143 | M23: 1 | N23: 478 | O23: No | P23: Tube Frame | Q23: Wings Only | R23: 10" | S23: 61 | T23: =$I23*0.453592 -> 190.96223 | U23: =$L23*0.453592 -> 64.863656 | V23: =IF($G23="","",($C23+$D23)/$G23) -> 0.4893617 | W23: =($C23+$D23) -> 276 | X23: =IF($G23="","",($C23+$E23)/$G23) -> 0.50177305 | Y23: =($C23+$E23) -> 283
A24: 30 | B24: Univ of New Hampshire | C24: 193 | D24: 114 | E24: 111 | F24: 193 | G24: 611 | I24: 444 | J24: EMPTY | L24: =IF($G24="","",$G24-$I24) -> 167 | M24: 1 | N24: 450 | O24: Yes, Cooler | P24: Tube Frame | Q24: Full Package | R24: 10" | S24: 62 | T24: =$I24*0.453592 -> 201.39485 | U24: =$L24*0.453592 -> 75.749864 | V24: =IF($G24="","",($C24+$D24)/$G24) -> 0.50245499 | W24: =($C24+$D24) -> 307 | X24: =IF($G24="","",($C24+$E24)/$G24) -> 0.49754501 | Y24: =($C24+$E24) -> 304
A25: 32 | B25: Pellissippi State Community College | C25: 197 | D25: 210 | E25: 184 | F25: 171 | G25: 762 | I25: 578 | J25: HALF | L25: =IF($G25="","",$G25-$I25) -> 184 | M25: 4 | N25: 600 | O25: No | P25: Tube Frame | Q25: None | R25: 10" | S25: =1600/25.4 -> 62.992126 | T25: =$I25*0.453592 -> 262.17618 | U25: =$L25*0.453592 -> 83.460928 | V25: =IF($G25="","",($C25+$D25)/$G25) -> 0.53412073 | W25: =($C25+$D25) -> 407 | X25: =IF($G25="","",($C25+$E25)/$G25) -> 0.5 | Y25: =($C25+$E25) -> 381
A26: 33 | B26: Oregon State Univ | C26: 104 | D26: 147 | E26: 162 | F26: 122 | G26: 533 | I26: 323 | J26: EMPTY | L26: =IF($G26="","",$G26-$I26) -> 210 | M26: 1 | N26: 450 | O26: No | P26: Monocoque | Q26: Full Package | R26: 10" | S26: =1535/25.4 -> 60.433071 | T26: =$I26*0.453592 -> 146.51022 | U26: =$L26*0.453592 -> 95.25432 | V26: =IF($G26="","",($C26+$D26)/$G26) -> 0.47091932 | W26: =($C26+$D26) -> 251 | X26: =IF($G26="","",($C26+$E26)/$G26) -> 0.49906191 | Y26: =($C26+$E26) -> 266
A27: 34 | B27: Univ of Central Florida | C27: 153 | D27: 151 | E27: 164 | F27: 164 | G27: 631 | I27: 468 | J27: EMPTY | L27: =IF($G27="","",$G27-$I27) -> 163 | M27: 4 | N27: 636 | O27: No | P27: Tube Frame | Q27: Full Package | R27: 10" | S27: 62 | T27: =$I27*0.453592 -> 212.28106 | U27: =$L27*0.453592 -> 73.935496 | V27: =IF($G27="","",($C27+$D27)/$G27) -> 0.48177496 | W27: =($C27+$D27) -> 304 | X27: =IF($G27="","",($C27+$E27)/$G27) -> 0.50237718 | Y27: =($C27+$E27) -> 317
A28: 35 | B28: Kansas State Univ | C28: 158 | D28: 182 | E28: 189 | F28: 176 | G28: 705 | I28: 549 | J28: HALF | L28: =IF($G28="","",$G28-$I28) -> 156 | M28: 3 | N28: 675 | O28: No | P28: Monocoque | Q28: Full Package | R28: 10" | S28: 64.5 | T28: =$I28*0.453592 -> 249.02201 | U28: =$L28*0.453592 -> 70.760352 | V28: =IF($G28="","",($C28+$D28)/$G28) -> 0.4822695 | W28: =($C28+$D28) -> 340 | X28: =IF($G28="","",($C28+$E28)/$G28) -> 0.49219858 | Y28: =($C28+$E28) -> 347
A29: 36 | B29: Missouri University of Science and Tech | C29: 143 | D29: 182 | E29: 175 | F29: 142 | G29: 640 | I29: 462 | J29: HALF | L29: =IF($G29="","",$G29-$I29) -> 178 | M29: 4 | N29: 599 | O29: No | P29: Tube Frame | Q29: Full Package | R29: 10" | S29: 64 | T29: =$I29*0.453592 -> 209.5595 | U29: =$L29*0.453592 -> 80.739376 | V29: =IF($G29="","",($C29+$D29)/$G29) -> 0.5078125 | W29: =($C29+$D29) -> 325 | X29: =IF($G29="","",($C29+$E29)/$G29) -> 0.496875 | Y29: =($C29+$E29) -> 318
A30: 37 | B30: Univ of Illinois - Urbana Champaign | C30: 105 | D30: 141 | E30: 187 | F30: 144 | G30: 574 | I30: 426 | J30: EMPTY | L30: =IF($G30="","",$G30-$I30) -> 148 | M30: 4 | N30: 600 | O30: No | P30: Hybrid | Q30: Full Package | R30: 13" | S30: 64 | T30: =$I30*0.453592 -> 193.23019 | U30: =$L30*0.453592 -> 67.131616 | V30: =IF($G30="","",($C30+$D30)/$G30) -> 0.42857143 | W30: =($C30+$D30) -> 246 | X30: =IF($G30="","",($C30+$E30)/$G30) -> 0.5087108 | Y30: =($C30+$E30) -> 292
A31: 38 | B31: Brown Univ | C31: 147 | D31: 156 | E31: 156 | F31: 144 | G31: 602 | I31: 438 | J31: EMPTY | L31: =IF($G31="","",$G31-$I31) -> 164 | M31: 4 | N31: 599 | O31: No | P31: Tube Frame | Q31: None | R31: 10" | S31: 63 | T31: =$I31*0.453592 -> 198.6733 | U31: =$L31*0.453592 -> 74.389088 | V31: =IF($G31="","",($C31+$D31)/$G31) -> 0.50332226 | W31: =($C31+$D31) -> 303 | X31: =IF($G31="","",($C31+$E31)/$G31) -> 0.50332226 | Y31: =($C31+$E31) -> 303
A32: 39 | B32: Univ of Missouri | C32: 164 | D32: 162 | E32: 171 | F32: 162 | G32: 660 | I32: 471 | J32: HALF | L32: =IF($G32="","",$G32-$I32) -> 189 | M32: 4 | N32: 600 | O32: No | P32: Tube Frame | Q32: Wings Only | R32: 10" | S32: 62.5 | T32: =$I32*0.453592 -> 213.64183 | U32: =$L32*0.453592 -> 85.728888 | V32: =IF($G32="","",($C32+$D32)/$G32) -> 0.49393939 | W32: =($C32+$D32) -> 326 | X32: =IF($G32="","",($C32+$E32)/$G32) -> 0.50757576 | Y32: =($C32+$E32) -> 335
A33: 40 | B33: Clemson Univ | C33: 149 | D33: 170 | E33: 187 | F33: 154 | G33: 659 | I33: 489 | J33: HALF | L33: =IF($G33="","",$G33-$I33) -> 170 | M33: 4 | N33: 600 | O33: No | P33: Tube Frame | Q33: Wings Only | R33: 10" | S33: 61.5 | T33: =$I33*0.453592 -> 221.80649 | U33: =$L33*0.453592 -> 77.11064 | V33: =IF($G33="","",($C33+$D33)/$G33) -> 0.48406677 | W33: =($C33+$D33) -> 319 | X33: =IF($G33="","",($C33+$E33)/$G33) -> 0.50986343 | Y33: =($C33+$E33) -> 336
A34: 41 | B34: Grand Valley State Univ | C34: 183 | D34: 206 | E34: 183 | F34: 162 | G34: 734 | I34: 547 | J34: EMPTY | L34: =IF($G34="","",$G34-$I34) -> 187 | M34: 4 | N34: 599 | O34: No | P34: Tube Frame | Q34: None | R34: 13" | S34: 60 | T34: =$I34*0.453592 -> 248.11482 | U34: =$L34*0.453592 -> 84.821704 | V34: =IF($G34="","",($C34+$D34)/$G34) -> 0.52997275 | W34: =($C34+$D34) -> 389 | X34: =IF($G34="","",($C34+$E34)/$G34) -> 0.4986376 | Y34: =($C34+$E34) -> 366
A35: 42 | B35: Univ of Kentucky | C35: 173 | D35: 169 | E35: 176 | F35: 172 | G35: 690 | I35: 524 | J35: HALF | L35: =IF($G35="","",$G35-$I35) -> 166 | M35: 4 | N35: 600 | O35: No | P35: Tube Frame | Q35: None | R35: 10" | S35: 60 | T35: =$I35*0.453592 -> 237.68221 | U35: =$L35*0.453592 -> 75.296272 | V35: =IF($G35="","",($C35+$D35)/$G35) -> 0.49565217 | W35: =($C35+$D35) -> 342 | X35: =IF($G35="","",($C35+$E35)/$G35) -> 0.5057971 | Y35: =($C35+$E35) -> 349
A36: 43 | B36: Minnesota State University - Mankato | C36: 128 | D36: 136 | E36: 137 | F36: 137 | G36: 538 | I36: 375 | J36: EMPTY | L36: =IF($G36="","",$G36-$I36) -> 163 | M36: 1 | N36: 449 | O36: No | P36: Tube Frame | Q36: None | R36: 10" | S36: 61.5 | T36: =$I36*0.453592 -> 170.097 | U36: =$L36*0.453592 -> 73.935496 | V36: =IF($G36="","",($C36+$D36)/$G36) -> 0.49070632 | W36: =($C36+$D36) -> 264 | X36: =IF($G36="","",($C36+$E36)/$G36) -> 0.49256506 | Y36: =($C36+$E36) -> 265
A37: 44 | B37: IPN - UPIITA | C37: 159 | D37: 226 | E37: 205 | F37: 136 | G37: 725 | I37: 563 | J37: HALF | L37: =IF($G37="","",$G37-$I37) -> 162 | M37: 4 | N37: 599 | O37: No | P37: Tube Frame | Q37: Wings Only | R37: 10" | S37: =1525/25.4 -> 60.03937 | T37: =$I37*0.453592 -> 255.3723 | U37: =$L37*0.453592 -> 73.481904 | V37: =IF($G37="","",($C37+$D37)/$G37) -> 0.53103448 | W37: =($C37+$D37) -> 385 | X37: =IF($G37="","",($C37+$E37)/$G37) -> 0.50206897 | Y37: =($C37+$E37) -> 364
A38: 46 | B38: San Jose State University | C38: 130 | D38: 148 | E38: 156 | F38: 140 | G38: 575 | I38: 435 | J38: HALF | L38: =IF($G38="","",$G38-$I38) -> 140 | M38: 3 | N38: 675 | O38: No | P38: Tube Frame | Q38: Full Package | R38: 10" | S38: 61.5 | T38: =$I38*0.453592 -> 197.31252 | U38: =$L38*0.453592 -> 63.50288 | V38: =IF($G38="","",($C38+$D38)/$G38) -> 0.48347826 | W38: =($C38+$D38) -> 278 | X38: =IF($G38="","",($C38+$E38)/$G38) -> 0.4973913 | Y38: =($C38+$E38) -> 286
A39: 47 | B39: Ryerson Univ | C39: 130 | D39: 146 | E39: 187 | F39: 173 | G39: 636 | I39: 452 | J39: HALF | L39: =IF($G39="","",$G39-$I39) -> 184 | M39: 4 | N39: 600 | O39: No | P39: Tube Frame | Q39: Wings Only | R39: 10" | S39: 60 | T39: =$I39*0.453592 -> 205.02358 | U39: =$L39*0.453592 -> 83.460928 | V39: =IF($G39="","",($C39+$D39)/$G39) -> 0.43396226 | W39: =($C39+$D39) -> 276 | X39: =IF($G39="","",($C39+$E39)/$G39) -> 0.49842767 | Y39: =($C39+$E39) -> 317
A40: 48 | B40: Vaughn College of Aeronautics | L40: =IF($G40="","",$G40-$I40) | T40: =$I40*0.453592 -> 0 | U40: =$L40*0.453592 -> #VALUE! | V40: =IF($G40="","",($C40+$D40)/$G40) | W40: =($C40+$D40) -> 0 | X40: =IF($G40="","",($C40+$E40)/$G40) | Y40: =($C40+$E40) -> 0
...

Sheet Label Creation
A1: CAR NUMBER FOR LABEL PRINT | B1: Car Number | C1: School Name | D1: Front % | E1: Front # | F1: Left % | G1: Left # | H1: Car Only | I1: Car w Driver | J1: Fuel Level
A2: 44 | B2: =VLOOKUP($A$2,'LOOKUP TABLE - DO NOT EDIT'!$A$2:$I$115,1,FALSE) -> 44 | C2: =VLOOKUP($A$2,'LOOKUP TABLE - DO NOT EDIT'!$A$2:$I$115,2,FALSE) -> IPN - UPIITA | D2: =VLOOKUP($A$2,'LOOKUP TABLE - DO NOT EDIT'!$A$2:$I$115,3,FALSE) -> 53.1 | E2: =VLOOKUP($A$2,'LOOKUP TABLE - DO NOT EDIT'!$A$2:$I$115,4,FALSE) -> 385 | F2: =VLOOKUP($A$2,'LOOKUP TABLE - DO NOT EDIT'!$A$2:$I$115,5,FALSE) -> 50.21 | G2: =VLOOKUP($A$2,'LOOKUP TABLE - DO NOT EDIT'!$A$2:$I$115,6,FALSE) -> 364 | H2: =VLOOKUP($A$2,'LOOKUP TABLE - DO NOT EDIT'!$A$2:$I$115,7,FALSE) -> 563 | I2: =VLOOKUP($A$2,'LOOKUP TABLE - DO NOT EDIT'!$A$2:$I$115,8,FALSE) -> 725 | J2: =VLOOKUP($A$2,'LOOKUP TABLE - DO NOT EDIT'!$A$2:$I$115,9,FALSE) -> HALF

Sheet Design Schedule
A1: Time | B1: Queue | C1: Team Number | D1: Team Name | E1: Car Weight | F1: Scaled?
A2: 8:30AM | B2: A | C2: 74 | D2: =VLOOKUP(C2,'Scales Input Table'!$A$2:$I$120,2,FALSE) -> Rochester Institute of Technology | E2: =VLOOKUP(C2,'Scales Input Table'!$A$2:$I$120,9,FALSE) -> 426 | F2: =IF(E2>0,"Yes","No") -> Yes
A3: 8:30AM | B3: B | C3: 46 | D3: =VLOOKUP(C3,'Scales Input Table'!$A$2:$I$120,2,FALSE) -> San Jose State University | E3: =VLOOKUP(C3,'Scales Input Table'!$A$2:$I$120,9,FALSE) -> 435 | F3: =IF(E3>0,"Yes","No") -> Yes
A4: 8:30AM | B4: C | C4: 88 | D4: =VLOOKUP(C4,'Scales Input Table'!$A$2:$I$120,2,FALSE) -> The Ohio State University | E4: =VLOOKUP(C4,'Scales Input Table'!$A$2:$I$120,9,FALSE) -> 441 | F4: =IF(E4>0,"Yes","No") -> Yes
A5: 8:30AM | B5: D | C5: 5 | D5: =VLOOKUP(C5,'Scales Input Table'!$A$2:$I$120,2,FALSE) -> Ecole De Technologie Superieure | E5: =VLOOKUP(C5,'Scales Input Table'!$A$2:$I$120,9,FALSE) -> 325 | F5: =IF(E5>0,"Yes","No") -> Yes
A6: 8:30AM | B6: E | C6: 22 | D6: =VLOOKUP(C6,'Scales Input Table'!$A$2:$I$120,2,FALSE) -> #N/A | E6: =VLOOKUP(C6,'Scales Input Table'!$A$2:$I$120,9,FALSE) -> #N/A | F6: =IF(E6>0,"Yes","No") -> #N/A | G6: No Paddock
A7: 8:30AM | B7: F | C7: 62 | D7: =VLOOKUP(C7,'Scales Input Table'!$A$2:$I$120,2,FALSE) -> Univ of Minnesota - Twin Cities | E7: =VLOOKUP(C7,'Scales Input Table'!$A$2:$I$120,9,FALSE) -> 448 | F7: =IF(E7>0,"Yes","No") -> Yes
A8: 8:30AM | B8: G | C8: 126 | D8: =VLOOKUP(C8,'Scales Input Table'!$A$2:$I$120,2,FALSE) -> Univ of Kansas - Lawrence | E8: =VLOOKUP(C8,'Scales Input Table'!$A$2:$I$120,9,FALSE) -> 465 | F8: =IF(E8>0,"Yes","No") -> Yes
A9: 8:30AM | B9: H | C9: 1 | D9: =VLOOKUP(C9,'Scales Input Table'!$A$2:$I$120,2,FALSE) -> Universitat Stuttgart | E9: =VLOOKUP(C9,'Scales Input Table'!$A$2:$I$120,9,FALSE) -> 383 | F9: =IF(E9>0,"Yes","No") -> Yes
A10: 8:30AM | B10: I | C10: 90 | D10: =VLOOKUP(C10,'Scales Input Table'!$A$2:$I$120,2,FALSE) -> Coburg University of Applied Sciences | E10: =VLOOKUP(C10,'Scales Input Table'!$A$2:$I$120,9,FALSE) -> 401 | F10: =IF(E10>0,"Yes","No") -> Yes
A11: 8:30AM | B11: J | C11: 8 | D11: =VLOOKUP(C11,'Scales Input Table'!$A$2:$I$120,2,FALSE) -> Univ of Wisconsin - Madison | E11: =VLOOKUP(C11,'Scales Input Table'!$A$2:$I$120,9,FALSE) -> 363 | F11: =IF(E11>0,"Yes","No") -> Yes
A12: 8:30AM | B12: K | C12: 36 | D12: =VLOOKUP(C12,'Scales Input Table'!$A$2:$I$120,2,FALSE) -> Missouri University of Science and Tech | E12: =VLOOKUP(C12,'Scales Input Table'!$A$2:$I$120,9,FALSE) -> 462 | F12: =IF(E12>0,"Yes","No") -> Yes
A13: 8:30AM | B13: L | C13: 6 | D13: =VLOOKUP(C13,'Scales Input Table'!$A$2:$I$120,2,FALSE) -> Univ of Akron | E13: =VLOOKUP(C13,'Scales Input Table'!$A$2:$I$120,9,FALSE) -> 373 | F13: =IF(E13>0,"Yes","No") -> Yes
A14: 8:30AM | B14: M | C14: 54 | D14: =VLOOKUP(C14,'Scales Input Table'!$A$2:$I$120,2,FALSE) -> Michigan Tech Univ | E14: =VLOOKUP(C14,'Scales Input Table'!$A$2:$I$120,9,FALSE) -> 503 | F14: =IF(E14>0,"Yes","No") -> Yes
A15: 8:30AM | B15: N | C15: 56 | D15: =VLOOKUP(C15,'Scales Input Table'!$A$2:$I$120,2,FALSE) -> National Univ of Singapore | E15: =VLOOKUP(C15,'Scales Input Table'!$A$2:$I$120,9,FALSE) -> 468 | F15: =IF(E15>0,"Yes","No") -> Yes
A16: 8:30AM | B16: O | C16: 19 | D16: =VLOOKUP(C16,'Scales Input Table'!$A$2:$I$120,2,FALSE) -> North Carolina State Univ - Raleigh | E16: =VLOOKUP(C16,'Scales Input Table'!$A$2:$I$120,9,FALSE) -> 466 | F16: =IF(E16>0,"Yes","No") -> Yes
A17: 9:30AM | B17: A | C17: 39 | D17: =VLOOKUP(C17,'Scales Input Table'!$A$2:$I$120,2,FALSE) -> Univ of Missouri | E17: =VLOOKUP(C17,'Scales Input Table'!$A$2:$I$120,9,FALSE) -> 471 | F17: =IF(E17>0,"Yes","No") -> Yes
A18: 9:30AM | B18: B | C18: 2 | D18: =VLOOKUP(C18,'Scales Input Table'!$A$2:$I$120,2,FALSE) -> Graz Technical Univ | E18: =VLOOKUP(C18,'Scales Input Table'!$A$2:$I$120,9,FALSE) -> 342 | F18: =IF(E18>0,"Yes","No") -> Yes
... A36: 10:30AM | B36: E | C36: 40 | D36: =VLOOKUP(C36,'Scales Input Table'!$A$2:$I$120,2,FALSE) -> Clemson Univ | E36: =VLOOKUP(C36,'Scales Input Table'!$A$2:$I$120,9,FALSE) -> 489 | F36: =IF(E36>0,"Yes","No") -> Yes
A37: 10:30AM | B37: F | C37: 87 | D37: =VLOOKUP(C37,'Scales Input Table'!$A$2:$I$120,2,FALSE) -> #N/A | E37: =VLOOKUP(C37,'Scales Input Table'!$A$2:$I$120,9,FALSE) -> #N/A | F37: =IF(E37>0,"Yes","No") -> #N/A | G37: No Paddock
A38: 10:30AM | B38: G | C38: 47 | D38: =VLOOKUP(C38,'Scales Input Table'!$A$2:$I$120,2,FALSE) -> Ryerson Univ | E38: =VLOOKUP(C38,'Scales Input Table'!$A$2:$I$120,9,FALSE) -> 452 | F38: =IF(E38>0,"Yes","No") -> Yes
A39: 10:30AM | B39: H | C39: 105 | D39: =VLOOKUP(C39,'Scales Input Table'!$A$2:$I$120,2,FALSE) -> Worcester Polytechnic Inst | E39: =VLOOKUP(C39,'Scales Input Table'!$A$2:$I$120,9,FALSE) -> 416 | F39: =IF(E39>0,"Yes","No") -> Yes
A40: 10:30AM | B40: I | C40: 52 | D40: =VLOOKUP(C40,'Scales Input Table'!$A$2:$I$120,2,FALSE) -> Western Michigan Univ | E40: =VLOOKUP(C40,'Scales Input Table'!$A$2:$I$120,9,FALSE) -> 474 | F40: =IF(E40>0,"Yes","No") -> Yes
A41: 10:30AM | B41: J | C41: 132 | D41: =VLOOKUP(C41,'Scales Input Table'!$A$2:$I$120,2,FALSE) -> Univ of Pittsburgh - Pittsburgh | E41: =VLOOKUP(C41,'Scales Input Table'!$A$2:$I$120,9,FALSE) -> 469 | F41: =IF(E41>0,"Yes","No") -> Yes
A42: 10:30AM | B42: K | C42: 30 | D42: =VLOOKUP(C42,'Scales Input Table'!$A$2:$I$120,2,FALSE) -> Univ of New Hampshire | E42: =VLOOKUP(C42,'Scales Input Table'!$A$2:$I$120,9,FALSE) -> 444 | F42: =IF(E42>0,"Yes","No") -> Yes
A43: 10:30AM | B43: L | C43: 123 | D43: =VLOOKUP(C43,'Scales Input Table'!$A$2:$I$120,2,FALSE) -> Villanova Univ | E43: =VLOOKUP(C43,'Scales Input Table'!$A$2:$I$120,9,FALSE) -> 425 | F43: =IF(E43>0,"Yes","No") -> Yes
A44: 10:30AM | B44: M | C44: 69 | D44: =VLOOKUP(C44,'Scales Input Table'!$A$2:$I$120,2,FALSE) -> Univ of Connecticut | E44: =VLOOKUP(C44,'Scales Input Table'!$A$2:$I$120,9,FALSE) -> 451 | F44: =IF(E44>0,"Yes","No") -> Yes
A45: 10:30AM | B45: N | C45: 59 | D45: =VLOOKUP(C45,'Scales Input Table'!$A$2:$I$120,2,FALSE) -> #N/A | E45: =VLOOKUP(C45,'Scales Input Table'!$A$2:$I$120,9,FALSE) -> #N/A | F45: =IF(E45>0,"Yes","No") -> #N/A | G45: No Paddock
A46: 10:30AM | B46: O | C46: 12 | D46: =VLOOKUP(C46,'Scales Input Table'!$A$2:$I$120,2,FALSE) -> Purdue Univ - W Lafayette | E46: =VLOOKUP(C46,'Scales Input Table'!$A$2:$I$120,9,FALSE) -> 455 | F46: =IF(E46>0,"Yes","No") -> Yes
A47: 12:30PM | B47: A | C47: 91 | D47: =VLOOKUP(C47,'Scales Input Table'!$A$2:$I$120,2,FALSE) -> Georgia Institute of Technology | E47: =VLOOKUP(C47,'Scales Input Table'!$A$2:$I$120,9,FALSE) -> 479 | F47: =IF(E47>0,"Yes","No") -> Yes
A48: 12:30PM | B48: B | C48: 80 | D48: =VLOOKUP(C48,'Scales Input Table'!$A$2:$I$120,2,FALSE) -> Virginia Tech | E48: =VLOOKUP(C48,'Scales Input Table'!$A$2:$I$120,9,FALSE) -> 377 | F48: =IF(E48>0,"Yes","No") -> Yes
A49: 12:30PM | B49: C | C49: 93 | D49: =VLOOKUP(C49,'Scales Input Table'!$A$2:$I$120,2,FALSE) -> Universite Du Quebec a Trois-Rivieres | E49: =VLOOKUP(C49,'Scales Input Table'!$A$2:$I$120,9,FALSE) -> 465 | F49: =IF(E49>0,"Yes","No") -> Yes
A50: 12:30PM | B50: D | C50: 115 | D50: =VLOOKUP(C50,'Scales Input Table'!$A$2:$I$120,2,FALSE) -> Univ of British Columbia | E50: =VLOOKUP(C50,'Scales Input Table'!$A$2:$I$120,9,FALSE) -> 451 | F50: =IF(E50>0,"Yes","No") -> Yes
A51: 12:30PM | B51: E | C51: 72 | D51: =VLOOKUP(C51,'Scales Input Table'!$A$2:$I$120,2,FALSE) -> Florida International Univ | E51: =VLOOKUP(C51,'Scales Input Table'!$A$2:$I$120,9,FALSE) -> 475 | F51: =IF(E51>0,"Yes","No") -> Yes
A52: 12:30PM | B52: F | C52: 125 | D52: =VLOOKUP(C52,'Scales Input Table'!$A$2:$I$120,2,FALSE) -> South Dakota State Univ | E52: =VLOOKUP(C52,'Scales Input Table'!$A$2:$I$120,9,FALSE) -> 467 | F52: =IF(E52>0,"Yes","No") -> Yes
A53: 12:30PM | B53: G | C53: 83 | D53: =VLOOKUP(C53,'Scales Input Table'!$A$2:$I$120,2,FALSE) -> Univ of British Columbia - Okanagan | E53: =VLOOKUP(C53,'Scales Input Table'!$A$2:$I$120,9,FALSE) -> 565 | F53: =IF(E53>0,"Yes","No") -> Yes
A54: 12:30PM | B54: H | C54: 48 | D54: =VLOOKUP(C54,'Scales Input Table'!$A$2:$I$120,2,FALSE) -> Vaughn College of Aeronautics | E54: =VLOOKUP(C54,'Scales Input Table'!$A$2:$I$120,9,FALSE) -> 0 | F54: =IF(E54>0,"Yes","No") -> No | G54: No Paddock
A55: 12:30PM | B55: I | C55: 129 | D55: =VLOOKUP(C55,'Scales Input Table'!$A$2:$I$120,2,FALSE) -> #N/A | E55: =VLOOKUP(C55,'Scales Input Table'!$A$2:$I$120,9,FALSE) -> #N/A | F55: =IF(E55>0,"Yes","No") -> #N/A | G55: No Paddock
A56: 12:30PM | B56: J | C56: 21 | D56: =VLOOKUP(C56,'Scales Input Table'!$A$2:$I$120,2,FALSE) -> Univ of Florida | E56: =VLOOKUP(C56,'Scales Input Table'!$A$2:$I$120,9,FALSE) -> 474 | F56: =IF(E56>0,"Yes","No") -> Yes
A57: 12:30PM | B57: K | C57: 99 | D57: =VLOOKUP(C57,'Scales Input Table'!$A$2:$I$120,2,FALSE) -> York College of Pennsylvania | E57: =VLOOKUP(C57,'Scales Input Table'!$A$2:$I$120,9,FALSE) -> 403 | F57: =IF(E57>0,"Yes","No") -> Yes
...

Sheet Dropdown sheet - DO NOT EDIT
A1: Fuel | B1: Frame | C1: Aero | D1: Engine Cylinders | E1: Wheel Size | F1: Turbo
A2: FULL | B2: Tube Frame | C2: None | D2: 1 | E2: 10" | F2: No
A3: HALF | B3: Monocoque | C3: Wings Only | D3: 2 | E3: 13" | F3: Yes, Cooler
A4: EMPTY | B4: Hybrid | C4: Tray Only | D4: 3 | E4: Other | F4: Yes, No Cooler
C5: Full Package | D5: 4
D6: >4

Sheet LOOKUP TABLE - DO NOT EDIT
A1: Car Number | B1: School Name | C1: Front % | D1: Front # | E1: Left % | F1: Left # | G1: Car Only | H1: Car w Driver | I1: Fuel Level
A2: ='Scales Input Table'!$A2 -> 1 | B2: ='Scales Input Table'!$B2 -> Universitat Stuttgart | C2: =ROUND('Scales Input Table'!$V2*100,2) -> 50.36 | D2: ='Scales Input Table'!$W2 -> 281 | E2: =ROUND('Scales Input Table'!$X2*100,2) -> 49.82 | F2: ='Scales Input Table'!$Y2 -> 278 | G2: ='Scales Input Table'!$I2 -> 383 | H2: ='Scales Input Table'!$G2 -> 558 | I2: ='Scales Input Table'!$J2 -> HALF
A3: ='Scales Input Table'!$A3 -> 2 | B3: ='Scales Input Table'!$B3 -> Graz Technical Univ | C3: =ROUND('Scales Input Table'!$V3*100,2) -> 45.4 | D3: ='Scales Input Table'!$W3 -> 232 | E3: =ROUND('Scales Input Table'!$X3*100,2) -> 49.71 | F3: ='Scales Input Table'!$Y3 -> 254 | G3: ='Scales Input Table'!$I3 -> 342 | H3: ='Scales Input Table'!$G3 -> 511 | I3: ='Scales Input Table'!$J3 -> HALF
A4: ='Scales Input Table'!$A4 -> 5 | B4: ='Scales Input Table'!$B4 -> Ecole De Technologie Superieure | C4: =ROUND('Scales Input Table'!$V4*100,2) -> 46.61 | D4: ='Scales Input Table'!$W4 -> 220 | E4: =ROUND('Scales Input Table'!$X4*100,2) -> 50 | F4: ='Scales Input Table'!$Y4 -> 236 | G4: ='Scales Input Table'!$I4 -> 325 | H4: ='Scales Input Table'!$G4 -> 472 | I4: ='Scales Input Table'!$J4 -> HALF
A5: ='Scales Input Table'!$A5 -> 6 | B5: ='Scales Input Table'!$B5 -> Univ of Akron | C5: =ROUND('Scales Input Table'!$V5*100,2) -> 52.97 | D5: ='Scales Input Table'!$W5 -> 294 | E5: =ROUND('Scales Input Table'!$X5*100,2) -> 49.37 | F5: ='Scales Input Table'!$Y5 -> 274 | G5: ='Scales Input Table'!$I5 -> 373 | H5: ='Scales Input Table'!$G5 -> 555 | I5: ='Scales Input Table'!$J5 -> HALF
A6: ='Scales Input Table'!$A6 -> 7 | B6: ='Scales Input Table'!$B6 -> Carleton Univ | C6: =ROUND('Scales Input Table'!$V6*100,2) -> 49.03 | D6: ='Scales Input Table'!$W6 -> 254 | E6: =ROUND('Scales Input Table'!$X6*100,2) -> 49.42 | F6: ='Scales Input Table'!$Y6 -> 256 | G6: ='Scales Input Table'!$I6 -> 358 | H6: ='Scales Input Table'!$G6 -> 518 | I6: ='Scales Input Table'!$J6 -> EMPTY
A7: ='Scales Input Table'!$A7 -> 8 | B7: ='Scales Input Table'!$B7 -> Univ of Wisconsin - Madison | C7: =ROUND('Scales Input Table'!$V7*100,2) -> 46.42 | D7: ='Scales Input Table'!$W7 -> 253 | E7: =ROUND('Scales Input Table'!$X7*100,2) -> 50.46 | F7: ='Scales Input Table'!$Y7 -> 275 | G7: ='Scales Input Table'!$I7 -> 363 | H7: ='Scales Input Table'!$G7 -> 545 | I7: ='Scales Input Table'!$J7 -> EMPTY
A8: ='Scales Input Table'!$A8 -> 9 | B8: ='Scales Input Table'!$B8 -> Univ of Michigan - Ann Arbor | C8: =ROUND('Scales Input Table'!$V8*100,2) -> 46.75 | D8: ='Scales Input Table'!$W8 -> 288 | E8: =ROUND('Scales Input Table'!$X8*100,2) -> 49.51 | F8: ='Scales Input Table'!$Y8 -> 305 | G8: ='Scales Input Table'!$I8 -> 433 | H8: ='Scales Input Table'!$G8 -> 616 | I8: ='Scales Input Table'!$J8 -> EMPTY
A9: ='Scales Input Table'!$A9 -> 10 | B9: ='Scales Input Table'!$B9 -> AGH Univ of Science and Technology | C9: =ROUND('Scales Input Table'!$V9*100,2) -> 44.37 | D9: ='Scales Input Table'!$W9 -> 260 | E9: =ROUND('Scales Input Table'!$X9*100,2) -> 50 | F9: ='Scales Input Table'!$Y9 -> 293 | G9: ='Scales Input Table'!$I9 -> 427 | H9: ='Scales Input Table'!$G9 -> 586 | I9: ='Scales Input Table'!$J9 -> FULL
A10: ='Scales Input Table'!$A10 -> 11 | B10: ='Scales Input Table'!$B10 -> Michigan State Univ | C10: =ROUND('Scales Input Table'!$V10*100,2) -> 50.08 | D10: ='Scales Input Table'!$W10 -> 300 | E10: =ROUND('Scales Input Table'!$X10*100,2) -> 50.25 | F10: ='Scales Input Table'!$Y10 -> 301 | G10: ='Scales Input Table'!$I10 -> 427 | H10: ='Scales Input Table'!$G10 -> 599 | I10: ='Scales Input Table'!$J10 -> HALF
A11: ='Scales Input Table'!$A11 -> 12 | B11: ='Scales Input Table'!$B11 -> Purdue Univ - W Lafayette | C11: =ROUND('Scales Input Table'!$V11*100,2) -> 50 | D11: ='Scales Input Table'!$W11 -> 306 | E11: =ROUND('Scales Input Table'!$X11*100,2) -> 50.33 | F11: ='Scales Input Table'!$Y11 -> 308 | G11: ='Scales Input Table'!$I11 -> 455 | H11: ='Scales Input Table'!$G11 -> 612 | I11: ='Scales Input Table'!$J11 -> HALF
A12: ='Scales Input Table'!$A12 -> 14 | B12: ='Scales Input Table'!$B12 -> Ecole Polytechnique Montreal | C12: =ROUND('Scales Input Table'!$V12*100,2) -> 50.57 | D12: ='Scales Input Table'!$W12 -> 310 | E12: =ROUND('Scales Input Table'!$X12*100,2) -> 49.92 | F12: ='Scales Input Table'!$Y12 -> 306 | G12: ='Scales Input Table'!$I12 -> 410 | H12: ='Scales Input Table'!$G12 -> 613 | I12: ='Scales Input Table'!$J12 -> EMPTY
A13: ='Scales Input Table'!$A13 -> 16 | B13: ='Scales Input Table'!$B13 -> Kookmin Univ | C13: =ROUND('Scales Input Table'!$V13*100,2) -> 48.14 | D13: ='Scales Input Table'!$W13 -> 284 | E13: =ROUND('Scales Input Table'!$X13*100,2) -> 49.66 | F13: ='Scales Input Table'!$Y13 -> 293 | G13: ='Scales Input Table'!$I13 -> 463 | H13: ='Scales Input Table'!$G13 -> 590 | I13: ='Scales Input Table'!$J13 -> EMPTY
... A120: ='Scales Input Table'!$A120 -> 0 | B120: ='Scales Input Table'!$B120 -> 0 | C120: =ROUND('Scales Input Table'!$V120*100,2) -> #VALUE! | D120: ='Scales Input Table'!$W120 -> 0 | E120: =ROUND('Scales Input Table'!$X120*100,2) -> #VALUE! | F120: ='Scales Input Table'!$Y120 -> 0 | G120: ='Scales Input Table'!$I120 -> 0 | H120: ='Scales Input Table'!$G120 -> 0 | I120: ='Scales Input Table'!$J120 -> 0

Sheet Summary Statistics and Graphs
A1: ALL CARS | C1: Car Only | E1: Front % | F1: Left %
A2: Mean | C2: ='Scales Input Table'!I124 -> 456.4717 | E2: ='Scales Input Table'!V124 -> 0.49213796 | F2: ='Scales Input Table'!X124 -> 0.49987771
A3: SD | C3: ='Scales Input Table'!I125 -> 65.733837 | E3: ='Scales Input Table'!V125 -> 0.024713997 | F3: ='Scales Input Table'!X125 -> 0.0052255247
A4: Max | C4: ='Scales Input Table'!I126 -> 712 | E4: ='Scales Input Table'!V126 -> 0.55 | F4: ='Scales Input Table'!X126 -> 0.51342812
A5: Min | C5: ='Scales Input Table'!I127 -> 323 | E5: ='Scales Input Table'!V127 -> 0.42857143 | F5: ='Scales Input Table'!X127 -> 0.48403361
A6: 0.95 | C6: ='Scales Input Table'!I128 -> 564.3 | E6: ='Scales Input Table'!V128 -> 0.53963919 | F6: ='Scales Input Table'!X128 -> 0.50862812
A7: 0.05 | C7: ='Scales Input Table'!I129 -> 343.7 | E7: ='Scales Input Table'!V129 -> 0.44395146 | F7: ='Scales Input Table'!X129 -> 0.49224503
A9: # singles | C9: =COUNTIF('Scales Input Table'!$M$2:$M$120,1) -> 23
A10: # twin | C10: =COUNTIF('Scales Input Table'!$M$2:$M$120,2) -> 8
A11: # triple | C11: =COUNTIF('Scales Input Table'!$M$2:$M$120,3) -> 2
A12: # fours | C12: =COUNTIF('Scales Input Table'!$M$2:$M$120,4) -> 73
A14: 450cc or less | C14: =COUNTIF('Scales Input Table'!$N$2:$N$120,"<451") -> 20
A15: 451cc to 610cc | C15: =COUNTIFS('Scales Input Table'!$N$2:$N$120,">450",'Scales Input Table'!$N$2:$N$120,"<611") -> 78
A16: more than 611cc | C16: =COUNTIF('Scales Input Table'!$N$2:$N$120,">610") -> 8
A18: Singles | E18: Full Aero | I18: 10"
A19: Mean | C19: =AVERAGEIF('Scales Input Table'!$M$2:$M$120,"=1",'Scales Input Table'!$I$2:$I$120) -> 389.3913 | E19: Mean | G19: =AVERAGEIF('Scales Input Table'!$Q$2:$Q$120,"Full Package",'Scales Input Table'!$I$2:$I$120) -> 447.07143 | I19: Mean | K19: =AVERAGEIF('Scales Input Table'!$R$2:$R$120,"=10""",'Scales Input Table'!$I$2:$I$120) -> 440.0875
A21: Twins | E21: Wings Only | I21: 13"
A22: Mean | C22: =AVERAGEIF('Scales Input Table'!$M$2:$M$120,"=2",'Scales Input Table'!$I$2:$I$120) -> 444.625 | E22: Mean | G22: =AVERAGEIF('Scales Input Table'!$Q$2:$Q$120,"Wings Only",'Scales Input Table'!$I$2:$I$120) -> 443.48 | I22: Mean | K22: =AVERAGEIF('Scales Input Table'!$R$2:$R$120,"=13""",'Scales Input Table'!$I$2:$I$120) -> 506.88462
A24: Triple | E24: Tray Only
A25: Mean | C25: =AVERAGEIF('Scales Input Table'!$M$2:$M$120,"=3",'Scales Input Table'!$I$2:$I$120) -> 492 | E25: Mean | G25: =AVERAGEIF('Scales Input Table'!$Q$2:$Q$120,"Tray Only",'Scales Input Table'!$I$2:$I$120) -> 482.83333
A27: Fours | E27: No Aero
A28: Mean | C28: =AVERAGEIF('Scales Input Table'!$M$2:$M$120,"=4",'Scales Input Table'!$I$2:$I$120) -> 477.93151 | E28: Mean | G28: =AVERAGEIF('Scales Input Table'!$Q$2:$Q$120,"None",'Scales Input Table'!$I$2:$I$120) -> 473.48485

Sheet Sheet4
A1: Car Number | B1: School Name | C1: Front Left | D1: Front Right | E1: Rear Left | F1: Rear Right | G1: Car w/Driver | H1: VOID | I1: Car Only | J1: Fuel Level | K1: VOID2 | L1: Driver Weight | M1: Engine Cylinders
B2: SD Weight (all cars) | G2: =STDEV(#REF!) -> #REF! | I2: =STDEV(#REF!) -> #REF!
A3: =COUNT(A1:A1) -> 0 | B3: TOTAL NUMBER OF CARS SCALED | G3: =COUNT(G1:G1) -> 0 | I3: =COUNT(I1:I1) -> 0
A4: 33 | B4: Oregon State Univ | C4: 104 | D4: 147 | E4: 162 | F4: 122 | G4: 533 | I4: 323 | J4: EMPTY | L4: =IF($G4="","",$G4-$I4) -> 210 | M4: 1
B5: Min Weight (all cars) | G5: =MIN(#REF!) -> #REF! | I5: =MIN(#REF!) -> #REF!
A6: 5 | B6: Ecole De Technologie Superieure | C6: 113 | D6: 107 | E6: 123 | F6: 130 | G6: 472 | I6: 325 | J6: HALF | L6: =IF($G6="","",$G6-$I6) -> 147 | M6: 1
A7: 65 | B7: Lehigh Univ | C7: 111 | D7: 133 | E7: 137 | F7: 119 | G7: 499 | I7: 333 | J7: EMPTY | L7: =IF($G7="","",$G7-$I7) -> 166 | M7: 1
A8: 2 | B8: Graz Technical Univ | C8: 102 | D8: 130 | E8: 152 | F8: 128 | G8: 511 | I8: 342 | J8: HALF | L8: =IF($G8="","",$G8-$I8) -> 169 | M8: 1
A9: 106 | B9: Kettering Univ | C9: 66 | D9: 152 | E9: 183 | F9: 102 | G9: 503 | I9: 343 | J9: HALF | L9: =IF($G9="","",$G9-$I9) -> 160 | M9: 1
B10: 5% Weight (all cars) | G10: =_xlfn.PERCENTILE.EXC(G1:G1,0.05) -> #NUM! | I10: =_xlfn.PERCENTILE.EXC(I1:I1,0.05) -> #NUM!
A11: 89 | B11: Tennessee Tech Univ | C11: 116 | D11: 141 | E11: 142 | F11: 115 | G11: 514 | I11: 345 | J11: EMPTY | L11: =IF($G11="","",$G11-$I11) -> 169 | M11: 2
A12: 7 | B12: Carleton Univ | C12: 119 | D12: 135 | E12: 137 | F12: 125 | G12: 518 | I12: 358 | J12: EMPTY | L12: =IF($G12="","",$G12-$I12) -> 160 | M12: 1
A13: 8 | B13: Univ of Wisconsin - Madison | C13: 127 | D13: 126 | E13: 148 | F13: 144 | G13: 545 | I13: 363 | J13: EMPTY | L13: =IF($G13="","",$G13-$I13) -> 182 | M13: 1
A14: 84 | B14: Univ of Toronto | C14: 127 | D14: 140 | E14: 133 | F14: 123 | G14: 524 | I14: 364 | J14: EMPTY | L14: =IF($G14="","",$G14-$I14) -> 160 | M14: 1
A15: 55 | B15: Rutgers Univ | C15: 107 | D15: 140 | E15: 144 | F15: 107 | G15: 498 | I15: 368 | J15: HALF | L15: =IF($G15="","",$G15-$I15) -> 130 | M15: 1
A16: 113 | B16: Dalhousie Univ | C16: 125 | D16: 134 | E16: 141 | F16: 134 | G16: 534 | I16: 370 | J16: EMPTY | L16: =IF($G16="","",$G16-$I16) -> 164 | M16: 1
A17: 6 | B17: Univ of Akron | C17: 142 | D17: 152 | E17: 132 | F17: 129 | G17: 555 | I17: 373 | J17: HALF | L17: =IF($G17="","",$G17-$I17) -> 182 | M17: 1
A18: 43 | B18: Minnesota State University - Mankato | C18: 128 | D18: 136 | E18: 137 | F18: 137 | G18: 538 | I18: 375 | J18: EMPTY | L18: =IF($G18="","",$G18-$I18) -> 163 | M18: 1
A19: 80 | B19: Virginia Tech | C19: 124 | D19: 156 | E19: 168 | F19: 136 | G19: 583 | I19: 377 | J19: HALF | L19: =IF($G19="","",$G19-$I19) -> 206 | M19: 1
A20: 1 | B20: Universitat Stuttgart | C20: 120 | D20: 161 | E20: 158 | F20: 119 | G20: 558 | I20: 383 | J20: HALF | L20: =IF($G20="","",$G20-$I20) -> 175 | M20: 4
A21: 24 | B21: Univ of Toledo | C21: 124 | D21: 144 | E21: 138 | F21: 132 | G21: 538 | I21: 386 | J21: EMPTY | L21: =IF($G21="","",$G21-$I21) -> 152 | M21: 1
A22: 58 | B22: Kennesaw State University | C22: 141 | D22: 145 | E22: 122 | F22: 119 | G22: 527 | I22: 390 | J22: HALF | L22: =IF($G22="","",$G22-$I22) -> 137 | M22: 4
... A59: 26 | B59: Purdue Univ - Northwest | C59: 175 | D59: 166 | E59: 136 | F59: 143 | G59: 620 | I59: 456 | J59: HALF | L59: =IF($G59="","",$G59-$I59) -> 164 | M59: 4
B60: Mean Weight (all cars) | G60: =AVERAGE(G1:G56) -> #REF! | I60: =AVERAGE(I1:I56) -> #REF!
A61: 81 | B61: Northwestern Univ | C61: 153 | D61: 155 | E61: 157 | F61: 159 | G61: 623 | I61: 458 | J61: HALF | L61: =IF($G61="","",$G61-$I61) -> 165 | M61: 4
A62: 66 | B62: Univ of Waterloo | C62: 122 | D62: 198 | E62: 198 | F62: 118 | G62: 636 | I62: 460 | J62: HALF | L62: =IF($G62="","",$G62-$I62) -> 176 | M62: 4
A63: 139 | B63: CEFET-MG | C63: 143 | D63: 161 | E63: 162 | F63: 147 | G63: 614 | I63: 461 | J63: EMPTY | L63: =IF($G63="","",$G63-$I63) -> 153 | M63: 4
A64: 36 | B64: Missouri University of Science and Tech | C64: 143 | D64: 182 | E64: 175 | F64: 142 | G64: 640 | I64: 462 | J64: HALF | L64: =IF($G64="","",$G64-$I64) -> 178 | M64: 4
A65: 16 | B65: Kookmin Univ | C65: 119 | D65: 165 | E65: 174 | F65: 131 | G65: 590 | I65: 463 | J65: EMPTY | L65: =IF($G65="","",$G65-$I65) -> 127 | M65: 4
A66: 101 | B66: Mississippi State Univ | C66: 166 | D66: 130 | E66: 138 | F66: 165 | G66: 600 | I66: 463 | J66: HALF | L66: =IF($G66="","",$G66-$I66) -> 137 | M66: 2
A67: 109 | B67: US Air Force Academy | C67: 143 | D67: 182 | E67: 178 | F67: 149 | G67: 652 | I67: 464 | J67: FULL | L67: =IF($G67="","",$G67-$I67) -> 188 | M67: 1
A68: 124 | B68: Univ of Nebraska - Lincoln | C68: 155 | D68: 145 | E68: 165 | F68: 169 | G68: 634 | I68: 464 | J68: HALF | L68: =IF($G68="","",$G68-$I68) -> 170 | M68: 4
A69: 93 | B69: Universite Du Quebec a Trois-Rivieres | C69: 134 | D69: 160 | E69: 170 | F69: 147 | G69: 611 | I69: 465 | J69: EMPTY | L69: =IF($G69="","",$G69-$I69) -> 146 | M69: 4
A70: 110 | B70: US Naval Academy | C70: 138 | D70: 180 | E70: 190 | F70: 161 | G70: 673 | I70: 465 | J70: EMPTY | L70: =IF($G70="","",$G70-$I70) -> 208 | M70: 2
A71: 126 | B71: Univ of Kansas - Lawrence | C71: 122 | D71: 159 | E71: 189 | F71: 144 | G71: 614 | I71: 465 | J71: EMPTY | L71: =IF($G71="","",$G71-$I71) -> 149 | M71: 4
A72: 19 | B72: North Carolina State Univ - Raleigh | C72: 143 | D72: 165 | E72: 165 | F72: 153 | G72: 625 | I72: 466 | J72: EMPTY | L72: =IF($G72="","",$G72-$I72) -> 159 | M72: 4
... A91: 122 | B91: Florida Atlantic Univ | C91: 147 | D91: 175 | E91: 188 | F91: 156 | G91: 667 | I91: 491 | J91: FULL | L91: =IF($G91="","",$G91-$I91) -> 176 | M91: 4
A92: 108 | B92: Colorado Mesa University | C92: 162 | D92: 172 | E92: 166 | F92: 147 | G92: 647 | I92: 498 | J92: HALF | M92: 4
A93: 51 | B93: Universidad Simon Bolivar | C93: 141 | D93: 155 | E93: 179 | F93: 165 | G93: 639 | I93: 499 | J93: EMPTY | L93: =IF($G93="","",$G93-$I93) -> 140 | M93: 4
A94: 117 | B94: Columbia Univ | C94: 158 | D94: 172 | E94: 184 | F94: 175 | G94: 688 | I94: 500 | J94: EMPTY | L94: =IF($G94="","",$G94-$I94) -> 188 | M94: 4
...

Sheet Export Sheet
A1: Car Number | B1: School Name | C1: Car Only | D1: Front % | E1: Left % | F1: Engine Cylinders | G1: Engine Disp (cc) | H1: Turbo | I1: Frame | J1: Aerodynamic Package | K1: Wheel Diameter | L1: Wheelbase | M1: Design Queue | N1: Design Time
A2: 1 | B2: Universitat Stuttgart | C2: =IF('Scales Input Table'!T2>0,'Scales Input Table'!T2,"") -> 173.72574 | D2: ='Scales Input Table'!V2 -> 0.50358423 | E2: ='Scales Input Table'!X2 -> 0.49820789 | F2: =IF('Scales Input Table'!M2>0,'Scales Input Table'!M2,"") -> 4 | G2: =IF('Scales Input Table'!N2>0,'Scales Input Table'!N2,"") -> 599 | H2: =IF('Scales Input Table'!O2>0,'Scales Input Table'!O2,"") -> No | I2: =IF('Scales Input Table'!P2>0,'Scales Input Table'!P2,"") -> Hybrid | J2: =IF('Scales Input Table'!Q2>0,'Scales Input Table'!Q2,"") -> Full Package | K2: =IF('Scales Input Table'!R2>0,'Scales Input Table'!R2,"") -> 10" | L2: =IF('Scales Input Table'!S2>0,'Scales Input Table'!S2,"") -> 64.173228 | M2: =_xlfn.XLOOKUP(Table2[[#This Row],[Car Number]],'Design Schedule'!$C$2:$C$121,'Design Schedule'!$B$2:$B$121) -> H | N2: =_xlfn.XLOOKUP(Table2[[#This Row],[Car Number]],'Design Schedule'!$C$2:$C$121,'Design Schedule'!$A$2:$A$121) -> 8:30AM
A3: 2 | B3: Graz Technical Univ | C3: =IF('Scales Input Table'!T3>0,'Scales Input Table'!T3,"") -> 155.12846 | D3: ='Scales Input Table'!V3 -> 0.45401174 | E3: ='Scales Input Table'!X3 -> 0.49706458 | F3: =IF('Scales Input Table'!M3>0,'Scales Input Table'!M3,"") -> 1 | G3: =IF('Scales Input Table'!N3>0,'Scales Input Table'!N3,"") -> 510 | H3: =IF('Scales Input Table'!O3>0,'Scales Input Table'!O3,"") -> No | I3: =IF('Scales Input Table'!P3>0,'Scales Input Table'!P3,"") -> Monocoque | J3: =IF('Scales Input Table'!Q3>0,'Scales Input Table'!Q3,"") -> Full Package | K3: =IF('Scales Input Table'!R3>0,'Scales Input Table'!R3,"") -> 10" | L3: =IF('Scales Input Table'!S3>0,'Scales Input Table'!S3,"") -> 61.023622 | M3: =_xlfn.XLOOKUP(Table2[[#This Row],[Car Number]],'Design Schedule'!$C$2:$C$121,'Design Schedule'!$B$2:$B$121) -> B | N3: =_xlfn.XLOOKUP(Table2[[#This Row],[Car Number]],'Design Schedule'!$C$2:$C$121,'Design Schedule'!$A$2:$A$121) -> 9:30AM
A4: 5 | B4: Ecole De Technologie Superieure | C4: =IF('Scales Input Table'!T4>0,'Scales Input Table'!T4,"") -> 147.4174 | D4: ='Scales Input Table'!V4 -> 0.46610169 | E4: ='Scales Input Table'!X4 -> 0.5 | F4: =IF('Scales Input Table'!M4>0,'Scales Input Table'!M4,"") -> 1 | G4: =IF('Scales Input Table'!N4>0,'Scales Input Table'!N4,"") -> 449 | H4: =IF('Scales Input Table'!O4>0,'Scales Input Table'!O4,"") -> Yes, No Cooler | I4: =IF('Scales Input Table'!P4>0,'Scales Input Table'!P4,"") -> Monocoque | J4: =IF('Scales Input Table'!Q4>0,'Scales Input Table'!Q4,"") -> Wings Only | K4: =IF('Scales Input Table'!R4>0,'Scales Input Table'!R4,"") -> 10" | L4: =IF('Scales Input Table'!S4>0,'Scales Input Table'!S4,"") -> 60.25 | M4: =_xlfn.XLOOKUP(Table2[[#This Row],[Car Number]],'Design Schedule'!$C$2:$C$121,'Design Schedule'!$B$2:$B$121) -> D | N4: =_xlfn.XLOOKUP(Table2[[#This Row],[Car Number]],'Design Schedule'!$C$2:$C$121,'Design Schedule'!$A$2:$A$121) -> 8:30AM
A5: 6 | B5: Univ of Akron | C5: =IF('Scales Input Table'!T5>0,'Scales Input Table'!T5,"") -> 169.18982 | D5: ='Scales Input Table'!V5 -> 0.52972973 | E5: ='Scales Input Table'!X5 -> 0.49369369 | F5: =IF('Scales Input Table'!M5>0,'Scales Input Table'!M5,"") -> 1 | G5: =IF('Scales Input Table'!N5>0,'Scales Input Table'!N5,"") -> 450 | H5: =IF('Scales Input Table'!O5>0,'Scales Input Table'!O5,"") -> No | I5: =IF('Scales Input Table'!P5>0,'Scales Input Table'!P5,"") -> Hybrid | J5: =IF('Scales Input Table'!Q5>0,'Scales Input Table'!Q5,"") -> Full Package | K5: =IF('Scales Input Table'!R5>0,'Scales Input Table'!R5,"") -> 13" | L5: =IF('Scales Input Table'!S5>0,'Scales Input Table'!S5,"") -> 60.2 | M5: =_xlfn.XLOOKUP(Table2[[#This Row],[Car Number]],'Design Schedule'!$C$2:$C$121,'Design Schedule'!$B$2:$B$121) -> L | N5: =_xlfn.XLOOKUP(Table2[[#This Row],[Car Number]],'Design Schedule'!$C$2:$C$121,'Design Schedule'!$A$2:$A$121) -> 8:30AM
A6: 7 | B6: Carleton Univ | C6: =IF('Scales Input Table'!T6>0,'Scales Input Table'!T6,"") -> 162.38594 | D6: ='Scales Input Table'!V6 -> 0.49034749 | E6: ='Scales Input Table'!X6 -> 0.49420849 | F6: =IF('Scales Input Table'!M6>0,'Scales Input Table'!M6,"") -> 1 | G6: =IF('Scales Input Table'!N6>0,'Scales Input Table'!N6,"") -> 450 | H6: =IF('Scales Input Table'!O6>0,'Scales Input Table'!O6,"") -> No | I6: =IF('Scales Input Table'!P6>0,'Scales Input Table'!P6,"") -> Tube Frame | J6: =IF('Scales Input Table'!Q6>0,'Scales Input Table'!Q6,"") -> Full Package | K6: =IF('Scales Input Table'!R6>0,'Scales Input Table'!R6,"") -> 10" | L6: =IF('Scales Input Table'!S6>0,'Scales Input Table'!S6,"") -> 61 | M6: =_xlfn.XLOOKUP(Table2[[#This Row],[Car Number]],'Design Schedule'!$C$2:$C$121,'Design Schedule'!$B$2:$B$121) -> I | N6: =_xlfn.XLOOKUP(Table2[[#This Row],[Car Number]],'Design Schedule'!$C$2:$C$121,'Design Schedule'!$A$2:$A$121) -> 1:30PM
A7: 8 | B7: Univ of Wisconsin - Madison | C7: =IF('Scales Input Table'!T7>0,'Scales Input Table'!T7,"") -> 164.6539 | D7: ='Scales Input Table'!V7 -> 0.46422018 | E7: ='Scales Input Table'!X7 -> 0.50458716 | F7: =IF('Scales Input Table'!M7>0,'Scales Input Table'!M7,"") -> 1 | G7: =IF('Scales Input Table'!N7>0,'Scales Input Table'!N7,"") -> 449 | H7: =IF('Scales Input Table'!O7>0,'Scales Input Table'!O7,"") -> Yes, No Cooler | I7: =IF('Scales Input Table'!P7>0,'Scales Input Table'!P7,"") -> Hybrid | J7: =IF('Scales Input Table'!Q7>0,'Scales Input Table'!Q7,"") -> Wings Only | K7: =IF('Scales Input Table'!R7>0,'Scales Input Table'!R7,"") -> 10" | L7: =IF('Scales Input Table'!S7>0,'Scales Input Table'!S7,"") -> 63 | M7: =_xlfn.XLOOKUP(Table2[[#This Row],[Car Number]],'Design Schedule'!$C$2:$C$121,'Design Schedule'!$B$2:$B$121) -> J | N7: =_xlfn.XLOOKUP(Table2[[#This Row],[Car Number]],'Design Schedule'!$C$2:$C$121,'Design Schedule'!$A$2:$A$121) -> 8:30AM
A8: 9 | B8: Univ of Michigan - Ann Arbor | C8: =IF('Scales Input Table'!T8>0,'Scales Input Table'!T8,"") -> 196.40534 | D8: ='Scales Input Table'!V8 -> 0.46753247 | E8: ='Scales Input Table'!X8 -> 0.49512987 | F8: =IF('Scales Input Table'!M8>0,'Scales Input Table'!M8,"") -> 4 | G8: =IF('Scales Input Table'!N8>0,'Scales Input Table'!N8,"") -> 599 | H8: =IF('Scales Input Table'!O8>0,'Scales Input Table'!O8,"") -> Yes, No Cooler | I8: =IF('Scales Input Table'!P8>0,'Scales Input Table'!P8,"") -> Hybrid | J8: =IF('Scales Input Table'!Q8>0,'Scales Input Table'!Q8,"") -> Full Package | K8: =IF('Scales Input Table'!R8>0,'Scales Input Table'!R8,"") -> 10" | L8: =IF('Scales Input Table'!S8>0,'Scales Input Table'!S8,"") -> 61 | M8: =_xlfn.XLOOKUP(Table2[[#This Row],[Car Number]],'Design Schedule'!$C$2:$C$121,'Design Schedule'!$B$2:$B$121) -> I | N8: =_xlfn.XLOOKUP(Table2[[#This Row],[Car Number]],'Design Schedule'!$C$2:$C$121,'Design Schedule'!$A$2:$A$121) -> 9:30AM
A9: 10 | B9: AGH Univ of Science and Technology | C9: =IF('Scales Input Table'!T9>0,'Scales Input Table'!T9,"") -> 193.68378 | D9: ='Scales Input Table'!V9 -> 0.44368601 | E9: ='Scales Input Table'!X9 -> 0.5 | F9: =IF('Scales Input Table'!M9>0,'Scales Input Table'!M9,"") -> 4 | G9: =IF('Scales Input Table'!N9>0,'Scales Input Table'!N9,"") -> 599 | H9: =IF('Scales Input Table'!O9>0,'Scales Input Table'!O9,"") -> No | I9: =IF('Scales Input Table'!P9>0,'Scales Input Table'!P9,"") -> Tube Frame | J9: =IF('Scales Input Table'!Q9>0,'Scales Input Table'!Q9,"") -> Wings Only | K9: =IF('Scales Input Table'!R9>0,'Scales Input Table'!R9,"") -> 10" | L9: =IF('Scales Input Table'!S9>0,'Scales Input Table'!S9,"") -> 61.417323 | M9: =_xlfn.XLOOKUP(Table2[[#This Row],[Car Number]],'Design Schedule'!$C$2:$C$121,'Design Schedule'!$B$2:$B$121) -> C | N9: =_xlfn.XLOOKUP(Table2[[#This Row],[Car Number]],'Design Schedule'!$C$2:$C$121,'Design Schedule'!$A$2:$A$121) -> 10:30AM
A10: 11 | B10: Michigan State Univ | C10: =IF('Scales Input Table'!T10>0,'Scales Input Table'!T10,"") -> 193.68378 | D10: ='Scales Input Table'!V10 -> 0.50083472 | E10: ='Scales Input Table'!X10 -> 0.50250417 | F10: =IF('Scales Input Table'!M10>0,'Scales Input Table'!M10,"") -> 4 | G10: =IF('Scales Input Table'!N10>0,'Scales Input Table'!N10,"") -> 599 | H10: =IF('Scales Input Table'!O10>0,'Scales Input Table'!O10,"") -> No | I10: =IF('Scales Input Table'!P10>0,'Scales Input Table'!P10,"") -> Hybrid | J10: =IF('Scales Input Table'!Q10>0,'Scales Input Table'!Q10,"") -> Full Package | K10: =IF('Scales Input Table'!R10>0,'Scales Input Table'!R10,"") -> 10" | L10: =IF('Scales Input Table'!S10>0,'Scales Input Table'!S10,"") -> 60.5 | M10: =_xlfn.XLOOKUP(Table2[[#This Row],[Car Number]],'Design Schedule'!$C$2:$C$121,'Design Schedule'!$B$2:$B$121) -> F | N10: =_xlfn.XLOOKUP(Table2[[#This Row],[Car Number]],'Design Schedule'!$C$2:$C$121,'Design Schedule'!$A$2:$A$121) -> 9:30AM
A11: 12 | B11: Purdue Univ - W Lafayette | C11: =IF('Scales Input Table'!T11>0,'Scales Input Table'!T11,"") -> 206.38436 | D11: ='Scales Input Table'!V11 -> 0.5 | E11: ='Scales Input Table'!X11 -> 0.50326797 | F11: =IF('Scales Input Table'!M11>0,'Scales Input Table'!M11,"") -> 4 | G11: =IF('Scales Input Table'!N11>0,'Scales Input Table'!N11,"") -> 599 | H11: =IF('Scales Input Table'!O11>0,'Scales Input Table'!O11,"") -> No | I11: =IF('Scales Input Table'!P11>0,'Scales Input Table'!P11,"") -> Tube Frame | J11: =IF('Scales Input Table'!Q11>0,'Scales Input Table'!Q11,"") -> Full Package | K11: =IF('Scales Input Table'!R11>0,'Scales Input Table'!R11,"") -> 10" | L11: =IF('Scales Input Table'!S11>0,'Scales Input Table'!S11,"") -> 61 | M11: =_xlfn.XLOOKUP(Table2[[#This Row],[Car Number]],'Design Schedule'!$C$2:$C$121,'Design Schedule'!$B$2:$B$121) -> O | N11: =_xlfn.XLOOKUP(Table2[[#This Row],[Car Number]],'Design Schedule'!$C$2:$C$121,'Design Schedule'!$A$2:$A$121) -> 10:30AM
A12: 14 | B12: Ecole Polytechnique Montreal | C12: =IF('Scales Input Table'!T12>0,'Scales Input Table'!T12,"") -> 185.97272 | D12: ='Scales Input Table'!V12 -> 0.50570962 | E12: ='Scales Input Table'!X12 -> 0.49918434 | F12: =IF('Scales Input Table'!M12>0,'Scales Input Table'!M12,"") -> 1 | G12: =IF('Scales Input Table'!N12>0,'Scales Input Table'!N12,"") -> 449 | H12: =IF('Scales Input Table'!O12>0,'Scales Input Table'!O12,"") -> No | I12: =IF('Scales Input Table'!P12>0,'Scales Input Table'!P12,"") -> Tube Frame | J12: =IF('Scales Input Table'!Q12>0,'Scales Input Table'!Q12,"") -> Wings Only | K12: =IF('Scales Input Table'!R12>0,'Scales Input Table'!R12,"") -> 10" | L12: =IF('Scales Input Table'!S12>0,'Scales Input Table'!S12,"") -> 62.165354 | M12: =_xlfn.XLOOKUP(Table2[[#This Row],[Car Number]],'Design Schedule'!$C$2:$C$121,'Design Schedule'!$B$2:$B$121) -> G | N12: =_xlfn.XLOOKUP(Table2[[#This Row],[Car Number]],'Design Schedule'!$C$2:$C$121,'Design Schedule'!$A$2:$A$121) -> 9:30AM
A13: 16 | B13: Kookmin Univ | C13: =IF('Scales Input Table'!T13>0,'Scales Input Table'!T13,"") -> 210.0131 | D13: ='Scales Input Table'!V13 -> 0.48135593 | E13: ='Scales Input Table'!X13 -> 0.49661017 | F13: =IF('Scales Input Table'!M13>0,'Scales Input Table'!M13,"") -> 4 | G13: =IF('Scales Input Table'!N13>0,'Scales Input Table'!N13,"") -> 600 | H13: =IF('Scales Input Table'!O13>0,'Scales Input Table'!O13,"") -> No | I13: =IF('Scales Input Table'!P13>0,'Scales Input Table'!P13,"") -> Hybrid | J13: =IF('Scales Input Table'!Q13>0,'Scales Input Table'!Q13,"") -> Full Package | K13: =IF('Scales Input Table'!R13>0,'Scales Input Table'!R13,"") -> 10" | L13: =IF('Scales Input Table'!S13>0,'Scales Input Table'!S13,"") -> 60.23622 | M13: =_xlfn.XLOOKUP(Table2[[#This Row],[Car Number]],'Design Schedule'!$C$2:$C$121,'Design Schedule'!$B$2:$B$121) -> E | N13: =_xlfn.XLOOKUP(Table2[[#This Row],[Car Number]],'Design Schedule'!$C$2:$C$121,'Design Schedule'!$A$2:$A$121) -> 9:30AM
... A114: 139 | B114: CEFET-MG | C114: =IF('Scales Input Table'!T114>0,'Scales Input Table'!T114,"") -> 209.10591 | D114: ='Scales Input Table'!V114 -> 0.49511401 | E114: ='Scales Input Table'!X114 -> 0.49674267 | F114: =IF('Scales Input Table'!M114>0,'Scales Input Table'!M114,"") -> 4 | G114: =IF('Scales Input Table'!N114>0,'Scales Input Table'!N114,"") -> 599 | H114: =IF('Scales Input Table'!O114>0,'Scales Input Table'!O114,"") -> No | I114: =IF('Scales Input Table'!P114>0,'Scales Input Table'!P114,"") -> Tube Frame | J114: =IF('Scales Input Table'!Q114>0,'Scales Input Table'!Q114,"") -> Full Package | K114: =IF('Scales Input Table'!R114>0,'Scales Input Table'!R114,"") -> 10" | L114: =IF('Scales Input Table'!S114>0,'Scales Input Table'!S114,"") -> 60.629921 | M114: =_xlfn.XLOOKUP(Table2[[#This Row],[Car Number]],'Design Schedule'!$C$2:$C$121,'Design Schedule'!$B$2:$B$121) -> J | N114: =_xlfn.XLOOKUP(Table2[[#This Row],[Car Number]],'Design Schedule'!$C$2:$C$121,'Design Schedule'!$A$2:$A$121) -> 1:30PM
